Workbook

Sheet ODHAV 
A1: NUTAN NAGARIK SAHAKARI BANK LTD (GUJARAT BRANCHES & HEAD OFFICE)
A3: BRANCH NAME : ODHAV BRANCH
A4: BRANCH CODE: 21
A5: SUMMARY OF INCOME FOR THE MONTH OF SEP 2026
A7: CODE NO. | B7: PARTICULARS | D7: GGST | E7: CGST | F7: IGST
A8: PL
A9: 3303 | B9: DD CANCEL CHARGES | D9: =+C9*9% | E9: =+D9 | F9: =IF(D9>0," ",C9*18%)
A10: 3200 | B10: COMMISION ON BILLS | D10: =+C10*9% | E10: =+D10 | F10: =IF(D10>0," ",C10*18%)
A11: 3215 | B11: COMMISION ON PAYORDER | D11: =+C11*9% | E11: =+D11 | F11: =IF(D11>0," ",C11*18%)
A12: 3220 | B12: COMMISION ON U.B.D. | D12: =+C12*9% | E12: =+D12 | F12: =IF(D12>0," ",C12*18%)
A13: 3225 | B13: COMMISION I.B.C. | D13: =+C13*9% | E13: =+D13 | F13: =IF(D13>0," ",C13*18%)
A14: 3230 | B14: COMMISION ON GUARANTEE | D14: =+C14*9% | E14: =+D14 | F14: 0
A15: 3235 | B15: COMMISION ON DEMAND DRAFT | D15: =+C15*9% | E15: =+D15 | F15: =IF(D15>0," ",C15*18%)
A16: 3240 | B16: COMMISION ON U.B.C. | D16: =+C16*9% | E16: =+D16 | F16: =IF(D16>0," ",C16*18%)
A17: 3245 | B17: COMMISION ON L.C. | D17: =+C17*9% | E17: =+D17 | F17: =IF(D17>0," ",C17*18%)
A18: 3250 | B18: COMMISSION ON GUARANTEE | D18: =+C18*9% | E18: =+D18 | F18: =IF(D18>0," ",C18*18%)
A19: 3270 | B19: PROCESSING CHARGE | D19: =+C19*9% | E19: =+D19 | J19: =+G19*9%
A20: 3271 | B20: RENEWAL FEES | D20: =+C20*9% | E20: =+D20 | F20: =IF(D20>0," ",C20*18%)
A21: 3274 | B21: INCOME FROM E-STAMPING
A22: 3276 | B22: COMMISION ON PAN | D22: =+C22*9% | E22: =+D22 | F22: =IF(D22>0," ",C22*18%)
A23: 3280 | B23: INSURANCE PREMIUM | D23: =+C23*9% | E23: =+D23 | F23: =IF(D23>0," ",C23*18%)
A24: 3281 | B24: ATM CHARGES | D24: =+C24*9% | E24: =+D24 | F24: 0
A25: 3285 | B25: COMMISION ON RTGS | D25: =+C25*9% | E25: =+D25 | F25: =IF(D25>0," ",C25*18%)
A26: 3286 | B26: COMMISION ON PMJJBY LIC | D26: =+C26*9% | E26: =+D26 | F26: =IF(D26>0," ",C26*18%)
A27: 3287 | B27: COMM. ON PMSBY NEW INDIA ASSURANCE | D27: =+C27*9% | E27: =+D27 | F27: =IF(D27>0," ",C27*18%)
A28: 3291 | B28: CIBIL CHARGES | D28: =+C28*9% | E28: =+D28 | F28: =IF(D28>0," ",C28*18%)
A29: 3296 | B29: RTGS/NEFT MANUAL CHARGES | D29: =+C29*9% | E29: =+D29 | F29: =IF(D29>0," ",C29*18%)
A30: 3297 | B30: ASBA FORM PRINT CHARGES | D30: =+C30*9% | E30: =+D30 | F30: =IF(D30>0," ",C30*18%)
A31: 3298 | B31: MANDATE HANDLING CHARGES | D31: =+C31*9% | E31: =+D31 | F31: =IF(D31>0," ",C31*18%)
A32: 3299 | B32: SI EXECUTION FAILED CHARGES | D32: =+C32*9% | E32: =+D32 | F32: =IF(D32>0," ",C32*18%)
A33: 3300 | B33: INCIDENTAL CHARGES | D33: =+C33*9% | E33: =+D33 | F33: =IF(D33>0," ",C33*18%)
A34: 3301 | B34: INOPERATIVE CHARGES | D34: =+C34*9% | E34: =+D34 | F34: =IF(D34>0," ",C34*18%)
A35: 3302 | B35: PO CANCEL CHARGES | D35: =+C35*9% | E35: =+D35 | F35: =IF(D35>0," ",C35*18%)
A36: 3305 | B36: A/C SHARE TRANSFER FEES | D36: =+C36*9% | E36: =+D36 | F36: =IF(D36>0," ",C36*18%)
A37: 3309 | B37: MIS. INCOME WITH GST | D37: =+C37*9% | E37: =+D37 | F37: =IF(D37>0," ",C37*18%)
A38: 3310 | B38: MIS. INCOME | D38: =+C38*9% | E38: =+D38 | F38: =IF(D38>0," ",C38*18%)
A39: 3311 | B39: I/W CHQ. RET. CHARGES | D39: =+C39*9% | E39: =+D39 | F39: =IF(D39>0," ",C39*18%)
A40: 3312 | B40: O/W CHQ. RET. CHARGES | D40: =+C40*9% | E40: =+D40 | F40: =IF(D40>0," ",C40*18%)
A41: 3313 | B41: ECS RETD. CHARGES | D41: =+C41*9% | E41: =+D41 | F41: =IF(D41>0," ",C41*18%) | J41: =3000*9%
A42: 3314 | B42: CHQ. BOOK ISSUE CHARGES | D42: =+C42*9% | E42: =+D42 | F42: =IF(D42>0," ",C42*18%) | K42: =9000*9%
...

Sheet RAKHIAL
A1: NUTAN NAGARIK SAHAKARI BANK LTD (GUJARAT BRANCHES & HEAD OFFICE)
A3: BRANCH NAME : RAKHIAL BRANCH
A4: BRANCH CODE: 06
A5: =+'ODHAV '!A5
A7: CODE NO. | B7: PARTICULARS | D7: GGST | E7: CGST | F7: IGST
A8: PL
A9: 3303 | B9: DD CANCEL CHARGES | D9: =+C9*9% | E9: =+D9 | F9: =IF(D9>0," ",C9*18%)
A10: 3200 | B10: COMMISION ON BILLS | D10: =+C10*9% | E10: =+D10 | F10: =IF(D10>0," ",C10*18%)
A11: 3215 | B11: COMMISION ON PAYORDER | D11: =+C11*9% | E11: =+D11 | F11: =IF(D11>0," ",C11*18%)
A12: 3220 | B12: COMMISION ON U.B.D. | D12: =+C12*9% | E12: =+D12 | F12: =IF(D12>0," ",C12*18%)
A13: 3225 | B13: COMMISION I.B.C. | D13: =+C13*9% | E13: =+D13 | F13: =IF(D13>0," ",C13*18%)
A14: 3230 | B14: COMMISION ON GUARANTEE | D14: =+C14*9% | E14: =+D14 | F14: 0
A15: 3235 | B15: COMMISION ON DEMAND DRAFT | D15: =+C15*9% | E15: =+D15 | F15: =IF(D15>0," ",C15*18%)
A16: 3240 | B16: COMMISION ON U.B.C. | D16: =+C16*9% | E16: =+D16 | F16: =IF(D16>0," ",C16*18%)
A17: 3245 | B17: COMMISION ON L.C. | D17: =+C17*9% | E17: =+D17 | F17: =IF(D17>0," ",C17*18%)
A18: 3250 | B18: COMMISSION ON GUARANTEE | D18: =+C18*9% | E18: =+D18 | F18: =IF(D18>0," ",C18*18%)
A19: 3270 | B19: PROCESSING CHARGE | D19: =+C19*9% | E19: =+D19 | F19: =IF(D19>0," ",C19*18%)
A20: 3271 | B20: RENEWAL FEES | D20: =+C20*9% | E20: =+D20
A21: 3274 | B21: INCOME FROM E-STAMPING | D21: =+C21*9% | E21: =+D21 | F21: =IF(D21>0," ",C21*18%)
A22: 3276 | B22: COMMISION ON PAN | D22: =+C22*9% | E22: =+D22 | F22: =IF(D22>0," ",C22*18%)
A23: 3280 | B23: INSURANCE PREMIUM | D23: =+C23*9% | E23: =+D23 | F23: =IF(D23>0," ",C23*18%)
A24: 3281 | B24: ATM CHARGES | D24: =+C24*9% | E24: =+D24 | F24: =IF(D24>0," ",C24*18%)
A25: 3285 | B25: COMMISION ON RTGS | D25: =+C25*9% | E25: =+D25 | F25: =IF(D25>0," ",C25*18%)
A26: 3286 | B26: COMMISION ON PMJJBY LIC | D26: =+C26*9% | E26: =+D26 | F26: =IF(D26>0," ",C26*18%)
A27: 3287 | B27: COMM. ON PMSBY NEW INDIA ASSURANCE | D27: =+C27*9% | E27: =+D27 | F27: =IF(D27>0," ",C27*18%)
A28: 3291 | B28: CIBIL CHARGES | D28: =+C28*9% | E28: =+D28 | F28: =IF(D28>0," ",C28*18%)
A29: 3296 | B29: RTGS/NEFT MANUAL CHARGES | D29: =+C29*9% | E29: =+D29 | F29: =IF(D29>0," ",C29*18%)
A30: 3297 | B30: ASBA FORM PRINT CHARGES | D30: =+C30*9% | E30: =+D30 | F30: =IF(D30>0," ",C30*18%)
A31: 3298 | B31: MANDATE HANDLING CHARGES | D31: =+C31*9% | E31: =+D31 | F31: =IF(D31>0," ",C31*18%)
A32: 3299 | B32: SI EXECUTION FAILED CHARGES | D32: =+C32*9% | E32: =+D32 | F32: =IF(D32>0," ",C32*18%)
A33: 3300 | B33: INCIDENTAL CHARGES | D33: =+C33*9% | E33: =+D33 | F33: 0
A34: 3301 | B34: INOPERATIVE CHARGES | D34: =+C34*9% | E34: =+D34 | F34: =IF(D34>0," ",C34*18%)
A35: 3302 | B35: PO CANCEL CHARGES | D35: =+C35*9% | E35: =+D35 | F35: =IF(D35>0," ",C35*18%)
A36: 3305 | B36: A/C SHARE TRANSFER FEES | D36: =+C36*9% | E36: =+D36 | F36: =IF(D36>0," ",C36*18%)
A37: 3309 | B37: MIS. INCOME WITH GST | D37: =+C37*9% | E37: =+D37 | F37: =IF(D37>0," ",C37*18%)
A38: 3310 | B38: MIS. INCOME | D38: =+C38*9% | E38: =+D38 | F38: =IF(D38>0," ",C38*18%)
A39: 3311 | B39: I/W CHQ. RET. CHARGES | D39: =+C39*9% | E39: =+D39 | F39: =IF(D39>0," ",C39*18%)
A40: 3312 | B40: O/W CHQ. RET. CHARGES | D40: =+C40*9% | E40: =+D40 | F40: =IF(D40>0," ",C40*18%)
A41: 3313 | B41: ECS RETD. CHARGES | D41: =+C41*9% | E41: =+D41 | F41: =IF(D41>0," ",C41*18%)
A42: 3314 | B42: CHQ. BOOK ISSUE CHARGES | D42: =+C42*9% | E42: =+D42 | F42: =IF(D42>0," ",C42*18%)
...

Sheet NEW SHARDA
A1: NUTAN NAGARIK SAHAKARI BANK LTD (GUJARAT BRANCHES & HEAD OFFICE) | L1: 6357077131
A3: BRANCH NAME : NEW SHARDA MANDIR BRANCH
A4: BRANCH CODE: 16
A5: =+CHANGODAR!A5
A7: CODE NO. | B7: PARTICULARS | D7: GGST | E7: CGST | F7: IGST | I7: LOCKER CLOSED
A8: PL
A9: 3303 | B9: DD CANCEL CHARGES | D9: =+C9*9% | E9: =+D9 | F9: =IF(D9>0," ",C9*18%)
A10: 3200 | B10: COMMISION ON BILLS | D10: =+C10*9% | E10: =+D10 | F10: =IF(D10>0," ",C10*18%)
A11: 3215 | B11: COMMISION ON PAYORDER | D11: =+C11*9% | E11: =+D11 | F11: =IF(D11>0," ",C11*18%)
A12: 3220 | B12: COMMISION ON U.B.D. | D12: =+C12*9% | E12: =+D12 | F12: =IF(D12>0," ",C12*18%)
A13: 3225 | B13: COMMISION I.B.C. | D13: =+C13*9% | E13: =+D13 | F13: =IF(D13>0," ",C13*18%)
A14: 3230 | B14: COMMISION ON GUARANTEE | D14: =+C14*9% | E14: =+D14 | F14: =IF(D14>0," ",C14*18%)
A15: 3235 | B15: COMMISION ON DEMAND DRAFT | D15: =+C15*9% | E15: =+D15 | F15: =IF(D15>0," ",C15*18%)
A16: 3240 | B16: COMMISION ON U.B.C. | D16: =+C16*9% | E16: =+D16 | F16: =IF(D16>0," ",C16*18%)
A17: 3245 | B17: COMMISION ON L.C. | D17: =+C17*9% | E17: =+D17 | F17: =IF(D17>0," ",C17*18%)
A18: 3250 | B18: COMMISSION ON GUARANTEE | D18: =+C18*9% | E18: =+D18 | F18: =IF(D18>0," ",C18*18%)
A19: 3270 | B19: PROCESSING CHARGE | D19: =+C19*9% | E19: =+D19 | F19: =IF(D19>0," ",C19*18%)
A20: 3271 | B20: RENEWAL FEES | D20: =+C20*9% | E20: =+D20 | F20: =IF(D20>0," ",C20*18%)
A21: 3274 | B21: INCOME FROM E-STAMPING
A22: 3276 | B22: COMMISION ON PAN | D22: =+C22*9% | E22: =+D22 | F22: =IF(D22>0," ",C22*18%)
A23: 3280 | B23: INSURANCE PREMIUM | D23: =+C23*9% | E23: =+D23 | F23: =IF(D23>0," ",C23*18%)
A24: 3281 | B24: ATM CHARGES | D24: =+C24*9% | E24: =+D24 | F24: 0
A25: 3285 | B25: COMMISION ON RTGS | D25: =+C25*9% | E25: =+D25 | F25: =IF(D25>0," ",C25*18%)
A26: 3286 | B26: COMMISION ON PMJJBY LIC | D26: =+C26*9% | E26: =+D26 | F26: =IF(D26>0," ",C26*18%)
A27: 3287 | B27: COMM. ON PMSBY NEW INDIA ASSURANCE | D27: =+C27*9% | E27: =+D27 | F27: =IF(D27>0," ",C27*18%)
A28: 3291 | B28: CIBIL CHARGES | D28: =+C28*9% | E28: =+D28 | F28: =IF(D28>0," ",C28*18%)
A29: 3296 | B29: RTGS/NEFT MANUAL CHARGES | D29: =+C29*9% | E29: =+D29 | F29: =IF(D29>0," ",C29*18%)
A30: 3297 | B30: ASBA FORM PRINT CHARGES | D30: =+C30*9% | E30: =+D30 | F30: =IF(D30>0," ",C30*18%)
A31: 3298 | B31: MANDATE HANDLING CHARGES | D31: =+C31*9% | E31: =+D31 | F31: =IF(D31>0," ",C31*18%)
A32: 3299 | B32: SI EXECUTION FAILED CHARGES | D32: =+C32*9% | E32: =+D32 | F32: =IF(D32>0," ",C32*18%)
A33: 3300 | B33: INCIDENTAL CHARGES | D33: =+C33*9% | E33: =+D33 | F33: 0
A34: 3301 | B34: INOPERATIVE CHARGES | D34: =+C34*9% | E34: =+D34 | F34: =IF(D34>0," ",C34*18%)
A35: 3302 | B35: PO CANCEL CHARGES | D35: =+C35*9% | E35: =+D35 | F35: =IF(D35>0," ",C35*18%)
A36: 3305 | B36: A/C SHARE TRANSFER FEES | D36: =+C36*9% | E36: =+D36 | F36: =IF(D36>0," ",C36*18%)
A37: 3309 | B37: MIS. INCOME WITH GST | D37: =+C37*9% | E37: =+D37 | F37: =IF(D37>0," ",C37*18%)
A38: 3310 | B38: MIS. INCOME | D38: =+C38*9% | E38: =+D38 | F38: 0
A39: 3311 | B39: I/W CHQ. RET. CHARGES | D39: =+C39*9% | E39: =+D39 | F39: =IF(D39>0," ",C39*18%)
A40: 3312 | B40: O/W CHQ. RET. CHARGES | D40: =+C40*9% | E40: =+D40 | F40: 0
A41: 3313 | B41: ECS RETD. CHARGES | D41: =+C41*9% | E41: =+D41 | F41: =IF(D41>0," ",C41*18%)
A42: 3314 | B42: CHQ. BOOK ISSUE CHARGES | D42: =+C42*9% | E42: =+D42 | F42: =IF(D42>0," ",C42*18%)
...

Sheet CHANGODAR
A1: NUTAN NAGARIK SAHAKARI BANK LTD (GUJARAT BRANCHES & HEAD OFFICE)
A3: BRANCH NAME : CHANGODAR BRANCH
A4: BRANCH CODE: 20
A5: =+RAKHIAL!A5
A7: CODE NO. | B7: PARTICULARS | D7: GGST | E7: CGST | F7: IGST
A8: PL
A9: 3303 | B9: DD CANCEL CHARGES | D9: =+C9*9% | E9: =+D9 | F9: =IF(D9>0," ",C9*18%)
A10: 3200 | B10: COMMISION ON BILLS | D10: =+C10*9% | E10: =+D10 | F10: 0
A11: 3215 | B11: COMMISION ON PAYORDER | D11: =+C11*9% | E11: =+D11 | F11: 0
A12: 3220 | B12: COMMISION ON U.B.D. | D12: =+C12*9% | E12: =+D12 | F12: =IF(D12>0," ",C12*18%)
A13: 3225 | B13: COMMISION I.B.C. | D13: =+C13*9% | E13: =+D13 | F13: =IF(D13>0," ",C13*18%)
A14: 3230 | B14: COMMISION ON GUARANTEE | D14: =+C14*9% | E14: =+D14 | F14: =IF(D14>0," ",C14*18%)
A15: 3235 | B15: COMMISION ON DEMAND DRAFT | D15: =+C15*9% | E15: =+D15 | F15: 0
A16: 3240 | B16: COMMISION ON U.B.C. | D16: =+C16*9% | E16: =+D16 | F16: =IF(D16>0," ",C16*18%)
A17: 3245 | B17: COMMISION ON L.C. | D17: =+C17*9% | E17: =+D17 | F17: 0
A18: 3250 | B18: COMMISSION ON GUARANTEE | D18: =+C18*9% | E18: =+D18 | F18: =IF(D18>0," ",C18*18%)
A19: 3270 | B19: PROCESSING CHARGE | D19: =+C19*9% | E19: =+D19 | F19: 0
A20: 3271 | B20: RENEWAL FEES | D20: =+C20*9% | E20: =+D20
A21: 3274 | B21: INCOME FROM E-STAMPING
A22: 3276 | B22: COMMISION ON PAN | D22: =+C22*9% | E22: =+D22 | F22: =IF(D22>0," ",C22*18%)
A23: 3280 | B23: INSURANCE PREMIUM | D23: =+C23*9% | E23: =+D23 | F23: =IF(D23>0," ",C23*18%)
A24: 3281 | B24: ATM CHARGES | D24: =+C24*9% | E24: =+D24 | F24: 0
A25: 3285 | B25: COMMISION ON RTGS | D25: =+C25*9% | E25: =+D25
A26: 3286 | B26: COMMISION ON PMJJBY LIC | D26: =+C26*9% | E26: =+D26 | F26: =IF(D26>0," ",C26*18%)
A27: 3287 | B27: COMM. ON PMSBY NEW INDIA ASSURANCE | D27: =+C27*9% | E27: =+D27 | F27: =IF(D27>0," ",C27*18%)
A28: 3291 | B28: CIBIL CHARGES | D28: =+C28*9% | E28: =+D28 | F28: =IF(D28>0," ",C28*18%)
A29: 3296 | B29: RTGS/NEFT MANUAL CHARGES | D29: =+C29*9% | E29: =+D29 | F29: =IF(D29>0," ",C29*18%)
A30: 3297 | B30: ASBA FORM PRINT CHARGES | D30: =+C30*9% | E30: =+D30 | F30: 0
A31: 3298 | B31: MANDATE HANDLING CHARGES | D31: =+C31*9% | E31: =+D31 | F31: =IF(D31>0," ",C31*18%)
A32: 3299 | B32: SI EXECUTION FAILED CHARGES | D32: =+C32*9% | E32: =+D32 | F32: =IF(D32>0," ",C32*18%)
A33: 3300 | B33: INCIDENTAL CHARGES | D33: =+C33*9% | E33: =+D33 | F33: 0
A34: 3301 | B34: INOPERATIVE CHARGES | D34: =+C34*9% | E34: =+D34 | F34: =IF(D34>0," ",C34*18%)
A35: 3302 | B35: PO CANCEL CHARGES | D35: =+C35*9% | E35: =+D35 | F35: =IF(D35>0," ",C35*18%)
A36: 3305 | B36: A/C SHARE TRANSFER FEES | D36: =+C36*9% | E36: =+D36 | F36: =IF(D36>0," ",C36*18%)
A37: 3309 | B37: MIS. INCOME WITH GST | D37: =+C37*9% | E37: =+D37 | F37: =IF(D37>0," ",C37*18%)
A38: 3310 | B38: MIS. INCOME | D38: =+C38*9% | E38: =+D38 | F38: 0
A39: 3311 | B39: I/W CHQ. RET. CHARGES | D39: =+C39*9% | E39: =+D39 | F39: 0
A40: 3312 | B40: O/W CHQ. RET. CHARGES | D40: =+C40*9% | E40: =+D40 | F40: 0
A41: 3313 | B41: ECS RETD. CHARGES | D41: =+C41*9% | E41: =+D41 | F41: 0
A42: 3314 | B42: CHQ. BOOK ISSUE CHARGES | D42: =+C42*9% | E42: =+D42 | F42: 0
...

Sheet ISANPUR
A1: NUTAN NAGARIK SAHAKARI BANK LTD (GUJARAT BRANCHES & HEAD OFFICE)
A3: BRANCH NAME : ISANPUR BRANCH
A4: BRANCH CODE: 13
A5: =+'NEW SHARDA'!A5:F5
A7: CODE NO. | B7: PARTICULARS | D7: GGST | E7: CGST | F7: IGST | I7: LOCKER CLOSED CREDIT
A8: PL
A9: 3303 | B9: PENAL INEREST ON CASH CREDIT | D9: =+C9*9% | E9: =+D9 | F9: =IF(D9>0," ",C9*18%)
A10: 3200 | B10: COMMISION ON BILLS | D10: =+C10*9% | E10: =+D10 | F10: =IF(D10>0," ",C10*18%) | O10: d | P10: 580 | R10: =+P10
A11: 3215 | B11: COMMISION ON PAYORDER | D11: =+C11*9% | E11: =+D11 | F11: =IF(D11>0," ",C11*18%) | O11: d | P11: 146 | R11: =+P11
A12: 3220 | B12: COMMISION ON U.B.D. | D12: =+C12*9% | E12: =+D12 | F12: =IF(D12>0," ",C12*18%) | O12: d | P12: 91700 | R12: =+P12
A13: 3225 | B13: COMMISION I.B.C. | D13: =+C13*9% | E13: =+D13 | F13: =IF(D13>0," ",C13*18%) | O13: d | P13: 2040 | R13: =+P13
A14: 3230 | B14: COMMISION ON GUARANTEE | D14: =+C14*9% | E14: =+D14 | F14: 0 | O14: d | P14: 330 | R14: =+P14
A15: 3235 | B15: COMMISION ON DEMAND DRAFT | D15: =+C15*9% | E15: =+D15 | F15: =IF(D15>0," ",C15*18%) | O15: d | P15: 1250 | R15: =+P15
A16: 3240 | B16: COMMISION ON U.B.C. | D16: =+C16*9% | E16: =+D16 | F16: =IF(D16>0," ",C16*18%) | O16: d | P16: 2973.9 | R16: =+P16
A17: 3245 | B17: COMMISION ON L.C. | D17: =+C17*9% | E17: =+D17 | F17: =IF(D17>0," ",C17*18%) | O17: d | P17: 7834.15 | R17: =+P17
A18: 3250 | B18: COMMISSION ON GUARANTEE | D18: =+C18*9% | E18: =+D18 | F18: =IF(D18>0," ",C18*18%) | O18: d | P18: 6850 | R18: =+P18
A19: 3270 | B19: PROCESSING CHARGE | D19: =+C19*9% | E19: =+D19 | F19: 0 | O19: d | P19: 3900 | R19: =+P19
A20: 3271 | B20: RENEWAL FEES | D20: =+C20*9% | E20: =+D20 | O20: d | P20: 36518.56 | R20: =+P20
A21: 3274 | B21: INCOME FROM E-STAMPING | O21: d | P21: 7410 | R21: =+P21
A22: 3276 | B22: COMMISION ON PAN | D22: =+C22*9% | E22: =+D22 | F22: =IF(D22>0," ",C22*18%) | O22: d | P22: 3986 | R22: =+P22
A23: 3280 | B23: INSURANCE PREMIUM | D23: =+C23*9% | E23: =+D23 | F23: =IF(D23>0," ",C23*18%) | O23: d | P23: 8698 | Q23: 6393 | R23: =+P23-Q26
A24: 3281 | B24: ATM CHARGES | D24: =+C24*9% | E24: =+D24 | O24: d | P24: 25305 | R24: =+P24
A25: 3285 | B25: COMMISION ON RTGS | D25: =+C25*9% | E25: =+D25 | F25: =IF(D25>0," ",C25*18%) | P25: 366 | R25: =+P25
A26: 3286 | B26: COMMISION ON PMJJBY LIC | D26: =+C26*9% | E26: =+D26 | F26: =IF(D26>0," ",C26*18%) | P26: 57300 | Q26: 8698 | R26: =+P26-Q23
A27: 3287 | B27: COMM. ON PMSBY NEW INDIA ASSURANCE | D27: =+C27*9% | E27: =+D27 | F27: =IF(D27>0," ",C27*18%) | P27: =SUM(P10:P26) | Q27: =SUM(Q23:Q26) | R27: =SUM(R10:R26)
A28: 3291 | B28: CIBIL CHARGES | D28: =+C28*9% | E28: =+D28 | F28: =IF(D28>0," ",C28*18%) | R28: =R27*9%
A29: 3296 | B29: RTGS/NEFT MANUAL CHARGES | D29: =+C29*9% | E29: =+D29 | F29: =IF(D29>0," ",C29*18%)
A30: 3297 | B30: ASBA FORM PRINT CHARGES | D30: =+C30*9% | E30: =+D30 | F30: =IF(D30>0," ",C30*18%)
A31: 3298 | B31: MANDATE HANDLING CHARGES | D31: =+C31*9% | E31: =+D31 | F31: =IF(D31>0," ",C31*18%)
A32: 3299 | B32: SI EXECUTION FAILED CHARGES | D32: =+C32*9% | E32: =+D32 | F32: =IF(D32>0," ",C32*18%)
A33: 3300 | B33: INCIDENTAL CHARGES | D33: =+C33*9% | E33: =+D33 | F33: 0
A34: 3301 | B34: INOPERATIVE CHARGES | D34: =+C34*9% | E34: =+D34 | F34: =IF(D34>0," ",C34*18%)
A35: 3302 | B35: PO CANCEL CHARGES | D35: =+C35*9% | E35: =+D35 | F35: =IF(D35>0," ",C35*18%)
A36: 3305 | B36: A/C SHARE TRANSFER FEES | D36: =+C36*9% | E36: =+D36 | F36: =IF(D36>0," ",C36*18%)
A37: 3309 | B37: MIS. INCOME WITH GST | D37: =+C37*9% | E37: =+D37 | F37: =IF(D37>0," ",C37*18%)
A38: 3310 | B38: MIS. INCOME | D38: =+C38*9% | E38: =+D38 | F38: =IF(D38>0," ",C38*18%)
A39: 3311 | B39: I/W CHQ. RET. CHARGES | D39: =+C39*9% | E39: =+D39 | F39: =IF(D39>0," ",C39*18%)
A40: 3312 | B40: O/W CHQ. RET. CHARGES | D40: =+C40*9% | E40: =+D40 | F40: =IF(D40>0," ",C40*18%)
A41: 3313 | B41: ECS RETD. CHARGES | D41: =+C41*9% | E41: =+D41 | F41: =IF(D41>0," ",C41*18%)
A42: 3314 | B42: CHQ. BOOK ISSUE CHARGES | D42: =+C42*9% | E42: =+D42 | F42: =IF(D42>0," ",C42*18%)
...

Sheet MANINAGAR
A1: NUTAN NAGARIK SAHAKARI BANK LTD (GUJARAT BRANCHES & HEAD OFFICE)
A3: BRANCH NAME : MANINAGAR BRANCH
A4: BRANCH CODE: 19
A5: =+ISANPUR!A5
A7: CODE NO. | B7: PARTICULARS | D7: GGST | E7: CGST | F7: IGST | I7: LOCKER CLOSED CREDIT
A8: PL
A9: 3303 | B9: DD CANCEL CHARGES | D9: =+C9*9% | E9: =+D9 | F9: =IF(D9>0," ",C9*18%)
A10: 3200 | B10: COMMISION ON BILLS | D10: =+C10*9% | E10: =+D10 | F10: =IF(D10>0," ",C10*18%)
A11: 3215 | B11: COMMISION ON PAYORDER | D11: =+C11*9% | E11: =+D11 | F11: =IF(D11>0," ",C11*18%)
A12: 3220 | B12: COMMISION ON U.B.D. | D12: =+C12*9% | E12: =+D12 | F12: =IF(D12>0," ",C12*18%)
A13: 3225 | B13: COMMISION I.B.C. | D13: =+C13*9% | E13: =+D13 | F13: =IF(D13>0," ",C13*18%)
A14: 3230 | B14: COMMISION ON GUARANTEE | D14: =+C14*9% | E14: =+D14 | F14: =IF(D14>0," ",C14*18%)
A15: 3235 | B15: COMMISION ON DEMAND DRAFT | D15: =+C15*9% | E15: =+D15 | F15: =IF(D15>0," ",C15*18%)
A16: 3240 | B16: COMMISION ON U.B.C. | D16: =+C16*9% | E16: =+D16 | F16: =IF(D16>0," ",C16*18%)
A17: 3245 | B17: COMMISION ON L.C. | D17: =+C17*9% | E17: =+D17 | F17: =IF(D17>0," ",C17*18%)
A18: 3250 | B18: COMMISSION ON GUARANTEE | D18: =+C18*9% | E18: =+D18 | F18: =IF(D18>0," ",C18*18%)
A19: 3270 | B19: PROCESSING CHARGE | D19: =+C19*9% | E19: =+D19 | F19: =IF(D19>0," ",C19*18%)
A20: 3271 | B20: RENEWAL FEES | D20: =+C20*9% | E20: =+D20 | F20: =IF(D20>0," ",C20*18%)
A21: 3274 | B21: INCOME FROM E-STAMPING | D21: =+C21*9% | E21: =+D21 | F21: =IF(D21>0," ",C21*18%)
A22: 3276 | B22: COMMISION ON PAN | D22: =+C22*9% | E22: =+D22 | F22: =IF(D22>0," ",C22*18%)
A23: 3280 | B23: INSURANCE PREMIUM | D23: =+C23*9% | E23: =+D23 | F23: =IF(D23>0," ",C23*18%)
A24: 3281 | B24: ATM CHARGES | D24: =+C24*9% | E24: =+D24 | F24: =IF(D24>0," ",C24*18%)
A25: 3285 | B25: COMMISION ON RTGS | D25: =+C25*9% | E25: =+D25 | F25: =IF(D25>0," ",C25*18%)
A26: 3286 | B26: COMMISION ON PMJJBY LIC | D26: =+C26*9% | E26: =+D26 | F26: =IF(D26>0," ",C26*18%)
A27: 3287 | B27: COMM. ON PMSBY NEW INDIA ASSURANCE | D27: =+C27*9% | E27: =+D27 | F27: =IF(D27>0," ",C27*18%)
A28: 3291 | B28: CIBIL CHARGES | D28: =+C28*9% | E28: =+D28 | F28: =IF(D28>0," ",C28*18%)
A29: 3296 | B29: RTGS/NEFT MANUAL CHARGES | D29: =+C29*9% | E29: =+D29 | F29: =IF(D29>0," ",C29*18%)
A30: 3297 | B30: ASBA FORM PRINT CHARGES | D30: =+C30*9% | E30: =+D30 | F30: =IF(D30>0," ",C30*18%)
A31: 3298 | B31: MANDATE HANDLING CHARGES | D31: =+C31*9% | E31: =+D31 | F31: =IF(D31>0," ",C31*18%)
A32: 3299 | B32: SI EXECUTION FAILED CHARGES | D32: =+C32*9% | E32: =+D32 | F32: =IF(D32>0," ",C32*18%)
A33: 3300 | B33: INCIDENTAL CHARGES | D33: =+C33*9% | E33: =+D33 | F33: =IF(D33>0," ",C33*18%)
A34: 3301 | B34: INOPERATIVE CHARGES | D34: =+C34*9% | E34: =+D34 | F34: =IF(D34>0," ",C34*18%)
A35: 3302 | B35: PO CANCEL CHARGES | D35: =+C35*9% | E35: =+D35 | F35: =IF(D35>0," ",C35*18%)
A36: 3305 | B36: A/C SHARE TRANSFER FEES | D36: =+C36*9% | E36: =+D36 | F36: =IF(D36>0," ",C36*18%)
A37: 3309 | B37: MIS. INCOME WITH GST | D37: =+C37*9% | E37: =+D37 | F37: =IF(D37>0," ",C37*18%)
A38: 3310 | B38: MIS. INCOME | D38: =+C38*9% | E38: =+D38 | F38: =IF(D38>0," ",C38*18%) | J38: =+C39-J39
A39: 3311 | B39: I/W CHQ. RET. CHARGES | D39: =+C39*9% | E39: =+D39 | F39: =IF(D39>0," ",C39*18%) | J39: 7150
A40: 3312 | B40: O/W CHQ. RET. CHARGES | D40: =+C40*9% | E40: =+D40 | F40: =IF(D40>0," ",C40*18%)
A41: 3313 | B41: ECS RETD. CHARGES | D41: =+C41*9% | E41: =+D41 | F41: =IF(D41>0," ",C41*18%)
A42: 3314 | B42: CHQ. BOOK ISSUE CHARGES | D42: =+C42*9% | E42: =+D42 | F42: =IF(D42>0," ",C42*18%)
...

Sheet SHANTI COMM
A1: NUTAN NAGARIK SAHAKARI BANK LTD (GUJARAT BRANCHES & HEAD OFFICE)
A3: BRANCH NAME : SHANTI COMMERCIAL BRANCH
A4: BRANCH CODE: 04
A5: =+MANINAGAR!A5
A7: CODE NO. | B7: PARTICULARS | D7: GGST | E7: CGST | F7: IGST | I7: LOCKER CLOSED CREDIT
A8: PL
A9: 3303 | B9: DD CANCEL CHARGES | D9: =+C9*9% | E9: =+D9 | F9: =IF(D9>0," ",C9*18%)
A10: 3200 | B10: COMMISION ON BILLS | D10: =+C10*9% | E10: =+D10 | F10: =IF(D10>0," ",C10*18%)
A11: 3215 | B11: COMMISION ON PAYORDER | D11: =+C11*9% | E11: =+D11 | F11: =IF(D11>0," ",C11*18%)
A12: 3220 | B12: COMMISION ON U.B.D. | D12: =+C12*9% | E12: =+D12 | F12: =IF(D12>0," ",C12*18%)
A13: 3225 | B13: COMMISION I.B.C. | D13: =+C13*9% | E13: =+D13 | F13: =IF(D13>0," ",C13*18%)
A14: 3230 | B14: COMMISION ON GUARANTEE | D14: =+C14*9% | E14: =+D14 | F14: 0
A15: 3235 | B15: COMMISION ON DEMAND DRAFT | D15: =+C15*9% | E15: =+D15 | F15: =IF(D15>0," ",C15*18%)
A16: 3240 | B16: COMMISION ON U.B.C. | D16: =+C16*9% | E16: =+D16 | F16: =IF(D16>0," ",C16*18%)
A17: 3245 | B17: COMMISION ON L.C. | D17: =+C17*9% | E17: =+D17 | F17: =IF(D17>0," ",C17*18%)
A18: 3250 | B18: COMMISSION ON GUARANTEE | D18: =+C18*9% | E18: =+D18 | F18: =IF(D18>0," ",C18*18%)
A19: 3270 | B19: PROCESSING CHARGE | D19: =+C19*9% | E19: =+D19 | F19: =IF(D19>0," ",C19*18%)
A20: 3271 | B20: RENEWAL FEES | D20: =+C20*9% | E20: =+D20 | F20: =IF(D20>0," ",C20*18%)
A21: 3274 | B21: INCOME FROM E-STAMPING | D21: =+C21*9% | E21: =+D21 | F21: =IF(D21>0," ",C21*18%)
A22: 3276 | B22: COMMISION ON PAN | D22: =+C22*9% | E22: =+D22 | F22: =IF(D22>0," ",C22*18%)
A23: 3280 | B23: INSURANCE PREMIUM | D23: =+C23*9% | E23: =+D23 | F23: =IF(D23>0," ",C23*18%)
A24: 3281 | B24: ATM CHARGES | D24: =+C24*9% | E24: =+D24 | F24: 0
A25: 3285 | B25: COMMISION ON RTGS | D25: =+C25*9% | E25: =+D25 | F25: =IF(D25>0," ",C25*18%)
A26: 3286 | B26: COMMISION ON PMJJBY LIC | D26: =+C26*9% | E26: =+D26 | F26: =IF(D26>0," ",C26*18%)
A27: 3287 | B27: COMM. ON PMSBY NEW INDIA ASSURANCE | D27: =+C27*9% | E27: =+D27 | F27: =IF(D27>0," ",C27*18%)
A28: 3291 | B28: CIBIL CHARGES | D28: =+C28*9% | E28: =+D28 | F28: =IF(D28>0," ",C28*18%)
A29: 3296 | B29: RTGS/NEFT MANUAL CHARGES | D29: =+C29*9% | E29: =+D29 | F29: =IF(D29>0," ",C29*18%)
A30: 3297 | B30: ASBA FORM PRINT CHARGES | D30: =+C30*9% | E30: =+D30 | F30: =IF(D30>0," ",C30*18%)
A31: 3298 | B31: MANDATE HANDLING CHARGES | D31: =+C31*9% | E31: =+D31 | F31: =IF(D31>0," ",C31*18%)
A32: 3299 | B32: SI EXECUTION FAILED CHARGES | D32: =+C32*9% | E32: =+D32 | F32: =IF(D32>0," ",C32*18%)
A33: 3300 | B33: INCIDENTAL CHARGES | D33: =+C33*9% | E33: =+D33 | F33: 0
A34: 3301 | B34: INOPERATIVE CHARGES | D34: =+C34*9% | E34: =+D34 | F34: =IF(D34>0," ",C34*18%)
A35: 3302 | B35: PO CANCEL CHARGES | D35: =+C35*9% | E35: =+D35 | F35: =IF(D35>0," ",C35*18%)
A36: 3305 | B36: A/C SHARE TRANSFER FEES | D36: =+C36*9% | E36: =+D36 | F36: =IF(D36>0," ",C36*18%)
A37: 3309 | B37: MIS. INCOME WITH GST | D37: =+C37*9% | E37: =+D37 | F37: =IF(D37>0," ",C37*18%)
A38: 3310 | B38: MIS. INCOME | D38: =+C38*9% | E38: =+D38 | F38: =IF(D38>0," ",C38*18%)
A39: 3311 | B39: I/W CHQ. RET. CHARGES | D39: =+C39*9% | E39: =+D39 | F39: =IF(D39>0," ",C39*18%)
A40: 3312 | B40: O/W CHQ. RET. CHARGES | D40: =+C40*9% | E40: =+D40 | F40: =IF(D40>0," ",C40*18%)
A41: 3313 | B41: ECS RETD. CHARGES | D41: =+C41*9% | E41: =+D41 | F41: =IF(D41>0," ",C41*18%)
A42: 3314 | B42: CHQ. BOOK ISSUE CHARGES | D42: =+C42*9% | E42: =+D42 | F42: =IF(D42>0," ",C42*18%)
...

Sheet MASKATI
A1: NUTAN NAGARIK SAHAKARI BANK LTD (GUJARAT BRANCHES & HEAD OFFICE)
A3: BRANCH NAME :MASKATI BRANCH
A4: BRANCH CODE:2
A5: =+'SHANTI COMM'!A5:F5
A7: CODE NO. | B7: PARTICULARS | D7: GGST | E7: CGST | F7: IGST | I7: LOCKER CLOSED CREDIT
A8: PL
A9: 3303 | B9: DD CANCEL CHARGES | D9: =+C9*9% | E9: =+D9 | F9: =IF(D9>0," ",C9*18%)
A10: 3200 | B10: COMMISION ON BILLS | D10: =+C10*9% | E10: =+D10 | F10: =IF(D10>0," ",C10*18%)
A11: 3215 | B11: COMMISION ON PAYORDER | D11: =+C11*9% | E11: =+D11 | F11: =IF(D11>0," ",C11*18%)
A12: 3220 | B12: COMMISION ON U.B.D. | D12: =+C12*9% | E12: =+D12 | F12: =IF(D12>0," ",C12*18%)
A13: 3225 | B13: COMMISION I.B.C. | D13: =+C13*9% | E13: =+D13 | F13: =IF(D13>0," ",C13*18%)
A14: 3230 | B14: COMMISION ON GUARANTEE | D14: =+C14*9% | E14: =+D14 | F14: 0
A15: 3235 | B15: COMMISION ON DEMAND DRAFT | D15: =+C15*9% | E15: =+D15 | F15: =IF(D15>0," ",C15*18%)
A16: 3240 | B16: COMMISION ON U.B.C. | D16: =+C16*9% | E16: =+D16 | F16: =IF(D16>0," ",C16*18%)
A17: 3245 | B17: COMMISION ON L.C. | D17: =+C17*9% | E17: =+D17 | F17: =IF(D17>0," ",C17*18%)
A18: 3250 | B18: COMMISSION ON GUARANTEE | D18: =+C18*9% | E18: =+D18 | F18: =IF(D18>0," ",C18*18%)
A19: 3270 | B19: PROCESSING CHARGE | D19: =+C19*9% | E19: =+D19 | F19: 0
A20: 3271 | B20: RENEWAL FEES | D20: =+C20*9% | E20: =+D20 | F20: 0
A21: 3274 | B21: INCOME FROM E-STAMPING
A22: 3276 | B22: COMMISION ON PAN | D22: =+C22*9% | E22: =+D22 | F22: =IF(D22>0," ",C22*18%)
A23: 3280 | B23: INSURANCE PREMIUM | D23: =+C23*9% | E23: =+D23 | F23: =IF(D23>0," ",C23*18%) | N23: 26113
A24: 3281 | B24: ATM CHARGES | D24: =+C24*9% | E24: =+D24 | F24: =IF(D24>0," ",C24*18%)
A25: 3285 | B25: COMMISION ON RTGS | D25: =+C25*9% | E25: =+D25 | F25: 0
A26: 3286 | B26: COMMISION ON PMJJBY LIC | D26: =+C26*9% | E26: =+D26 | F26: =IF(D26>0," ",C26*18%)
A27: 3287 | B27: COMM. ON PMSBY NEW INDIA ASSURANCE | D27: =+C27*9% | E27: =+D27 | F27: =IF(D27>0," ",C27*18%)
A28: 3291 | B28: CIBIL CHARGES | D28: =+C28*9% | E28: =+D28 | F28: =IF(D28>0," ",C28*18%)
A29: 3296 | B29: RTGS/NEFT MANUAL CHARGES | D29: =+C29*9% | E29: =+D29 | F29: =IF(D29>0," ",C29*18%)
A30: 3297 | B30: ASBA FORM PRINT CHARGES | D30: =+C30*9% | E30: =+D30 | F30: =IF(D30>0," ",C30*18%)
A31: 3298 | B31: MANDATE HANDLING CHARGES | D31: =+C31*9% | E31: =+D31 | F31: =IF(D31>0," ",C31*18%)
A32: 3299 | B32: SI EXECUTION FAILED CHARGES | D32: =+C32*9% | E32: =+D32 | F32: =IF(D32>0," ",C32*18%)
A33: 3300 | B33: INCIDENTAL CHARGES | D33: =+C33*9% | E33: =+D33 | F33: 0
A34: 3301 | B34: INOPERATIVE CHARGES | D34: =+C34*9% | E34: =+D34 | F34: =IF(D34>0," ",C34*18%)
A35: 3302 | B35: PO CANCEL CHRAGES | D35: =+C35*9% | E35: =+D35 | F35: =IF(D35>0," ",C35*18%)
A36: 3305 | B36: A/C SHARE TRANSFER FEES | D36: =+C36*9% | E36: =+D36 | F36: =IF(D36>0," ",C36*18%)
A37: 3309 | B37: MIS. INCOME WITH GST | D37: =+C37*9% | E37: =+D37 | F37: =IF(D37>0," ",C37*18%)
A38: 3310 | B38: MIS. INCOME | D38: =+C38*9% | E38: =+D38 | F38: =IF(D38>0," ",C38*18%)
A39: 3311 | B39: I/W CHQ. RET. CHARGES | D39: =+C39*9% | E39: =+D39 | F39: =IF(D39>0," ",C39*18%)
A40: 3312 | B40: O/W CHQ. RET. CHARGES | D40: =+C40*9% | E40: =+D40 | F40: =IF(D40>0," ",C40*18%)
A41: 3313 | B41: ECS RETD. CHARGES | D41: =+C41*9% | E41: =+D41 | F41: =IF(D41>0," ",C41*18%)
A42: 3314 | B42: CHQ. BOOK ISSUE CHARGES | D42: =+C42*9% | E42: =+D42 | F42: =IF(D42>0," ",C42*18%)
...

Sheet VEJALPUR
A1: NUTAN NAGARIK SAHAKARI BANK LTD (GUJARAT BRANCHES & HEAD OFFICE)
A3: BRANCH NAME : VEJALPUR BRANCH
A4: BRANCH CODE: 17
A5: =+MASKATI!A5
A7: CODE NO. | B7: PARTICULARS | D7: GGST | E7: CGST | F7: IGST | I7: LOCKER CLOSED CREDIT
A8: PL
A9: 3303 | B9: DD CANCEL CHARGES | D9: =+C9*9% | E9: =+D9 | F9: =IF(D9>0," ",C9*18%)
A10: 3200 | B10: COMMISION ON BILLS | D10: =+C10*9% | E10: =+D10 | F10: =IF(D10>0," ",C10*18%)
A11: 3215 | B11: COMMISION ON PAYORDER | D11: =+C11*9% | E11: =+D11 | F11: =IF(D11>0," ",C11*18%)
A12: 3220 | B12: COMMISION ON U.B.D. | D12: =+C12*9% | E12: =+D12 | F12: =IF(D12>0," ",C12*18%)
A13: 3225 | B13: COMMISION I.B.C. | D13: =+C13*9% | E13: =+D13 | F13: =IF(D13>0," ",C13*18%)
A14: 3230 | B14: COMMISION ON GUARANTEE | D14: =+C14*9% | E14: =+D14 | F14: =IF(D14>0," ",C14*18%)
A15: 3235 | B15: COMMISION ON DEMAND DRAFT | D15: =+C15*9% | E15: =+D15 | F15: =IF(D15>0," ",C15*18%)
A16: 3240 | B16: COMMISION ON U.B.C. | D16: =+C16*9% | E16: =+D16 | F16: =IF(D16>0," ",C16*18%)
A17: 3245 | B17: COMMISION ON L.C. | D17: =+C17*9% | E17: =+D17 | F17: =IF(D17>0," ",C17*18%)
A18: 3250 | B18: COMMISSION ON GUARANTEE | D18: =+C18*9% | E18: =+D18 | F18: =IF(D18>0," ",C18*18%)
A19: 3270 | B19: PROCESSING CHARGE | D19: =+C19*9% | E19: =+D19
A20: 3271 | B20: RENEWAL FEES | D20: =+C20*9% | E20: =+D20
A21: 3274 | B21: INCOME FROM E-STAMPING
A22: 3276 | B22: COMMISION ON PAN | D22: =+C22*9% | E22: =+D22
A23: 3280 | B23: INSURANCE PREMIUM | D23: =+C23*9% | E23: =+D23 | F23: =IF(D23>0," ",C23*18%)
A24: 3281 | B24: ATM CHARGES | D24: =+C24*9% | E24: =+D24 | F24: =IF(D24>0," ",C24*18%)
A25: 3285 | B25: COMMISION ON RTGS | D25: =+C25*9% | E25: =+D25 | F25: =IF(D25>0," ",C25*18%)
A26: 3286 | B26: COMMISION ON PMJJBY LIC | D26: =+C26*9% | E26: =+D26 | F26: =IF(D26>0," ",C26*18%)
A27: 3287 | B27: COMM. ON PMSBY NEW INDIA ASSURANCE | D27: =+C27*9% | E27: =+D27 | F27: =IF(D27>0," ",C27*18%)
A28: 3291 | B28: CIBIL CHARGES | D28: =+C28*9% | E28: =+D28 | F28: =IF(D28>0," ",C28*18%)
A29: 3296 | B29: RTGS/NEFT MANUAL CHARGES | D29: =+C29*9% | E29: =+D29 | F29: =IF(D29>0," ",C29*18%)
A30: 3297 | B30: ASBA FORM PRINT CHARGES | D30: =+C30*9% | E30: =+D30 | F30: =IF(D30>0," ",C30*18%)
A31: 3298 | B31: MANDATE HANDLING CHARGES | D31: =+C31*9% | E31: =+D31 | F31: =IF(D31>0," ",C31*18%)
A32: 3299 | B32: SI EXECUTION FAILED CHARGES | D32: =+C32*9% | E32: =+D32 | F32: =IF(D32>0," ",C32*18%)
A33: 3300 | B33: INCIDENTAL CHARGES | D33: =+C33*9% | E33: =+D33 | F33: =IF(D33>0," ",C33*18%)
A34: 3301 | B34: INOPERATIVE CHARGES | D34: =+C34*9% | E34: =+D34 | F34: =IF(D34>0," ",C34*18%)
A35: 3302 | B35: PO CANCEL CHRAGES | D35: =+C35*9% | E35: =+D35 | F35: =IF(D35>0," ",C35*18%)
A36: 3305 | B36: A/C SHARE TRANSFER FEES | D36: =+C36*9% | E36: =+D36 | F36: =IF(D36>0," ",C36*18%)
A37: 3309 | B37: MIS. INCOME WITH GST | D37: =+C37*9% | E37: =+D37 | F37: =IF(D37>0," ",C37*18%)
A38: 3310 | B38: MIS. INCOME | D38: =+C38*9% | E38: =+D38 | F38: =IF(D38>0," ",C38*18%)
A39: 3311 | B39: I/W CHQ. RET. CHARGES | D39: =+C39*9% | E39: =+D39 | F39: =IF(D39>0," ",C39*18%)
A40: 3312 | B40: O/W CHQ. RET. CHARGES | D40: =+C40*9% | E40: =+D40 | F40: =IF(D40>0," ",C40*18%)
A41: 3313 | B41: ECS RETD. CHARGES | D41: =+C41*9% | E41: =+D41 | F41: =IF(D41>0," ",C41*18%)
A42: 3314 | B42: CHQ. BOOK ISSUE CHARGES | D42: =+C42*9% | E42: =+D42 | F42: =IF(D42>0," ",C42*18%)
...

Sheet JODHPUR-SATELLITE
A1: NUTAN NAGARIK SAHAKARI BANK LTD (GUJARAT BRANCHES & HEAD OFFICE)
A3: BRANCH NAME : JODHPUR BRANCH
A4: BRANCH CODE: 11
A5: =+VEJALPUR!A5
A7: CODE NO. | B7: PARTICULARS | D7: GGST | E7: CGST | F7: IGST | I7: LCOKER CLOSED CREDIT
A8: PL
A9: 3303 | B9: DD CANCEL CHARGES | D9: =+C9*9% | E9: =+D9 | F9: =IF(D9>0," ",C9*18%)
A10: 3200 | B10: COMMISION ON BILLS | D10: =+C10*9% | E10: =+D10 | F10: =IF(D10>0," ",C10*18%)
A11: 3215 | B11: COMMISION ON PAYORDER | D11: =+C11*9% | E11: =+D11 | F11: =IF(D11>0," ",C11*18%)
A12: 3220 | B12: COMMISION ON U.B.D. | D12: =+C12*9% | E12: =+D12 | F12: =IF(D12>0," ",C12*18%)
A13: 3225 | B13: COMMISION I.B.C. | D13: =+C13*9% | E13: =+D13 | F13: =IF(D13>0," ",C13*18%)
A14: 3230 | B14: COMMISION ON GUARANTEE | D14: =+C14*9% | E14: =+D14 | F14: =IF(D14>0," ",C14*18%)
A15: 3235 | B15: COMMISION ON DEMAND DRAFT | D15: =+C15*9% | E15: =+D15 | F15: =IF(D15>0," ",C15*18%)
A16: 3240 | B16: COMMISION ON U.B.C. | D16: =+C16*9% | E16: =+D16 | F16: =IF(D16>0," ",C16*18%)
A17: 3245 | B17: COMMISION ON L.C. | D17: =+C17*9% | E17: =+D17 | F17: =IF(D17>0," ",C17*18%)
A18: 3250 | B18: COMMISSION ON GUARANTEE | D18: =+C18*9% | E18: =+D18 | F18: =IF(D18>0," ",C18*18%)
A19: 3270 | B19: PROCESSING CHARGE | D19: =+C19*9% | E19: =+D19 | F19: =IF(D19>0," ",C19*18%)
A20: 3271 | B20: RENEWAL FEES | D20: =+C20*9% | E20: =+D20 | F20: =IF(D20>0," ",C20*18%)
A21: 3274 | B21: INCOME FROM E-STAMPING
A22: 3276 | B22: COMMISION ON PAN | D22: =+C22*9% | E22: =+D22 | F22: =IF(D22>0," ",C22*18%)
A23: 3280 | B23: INSURANCE PREMIUM | D23: =+C23*9% | E23: =+D23 | F23: =IF(D23>0," ",C23*18%)
A24: 3281 | B24: ATM CHARGES | D24: =+C24*9% | E24: =+D24 | F24: =IF(D24>0," ",C24*18%)
A25: 3285 | B25: COMMISION ON RTGS | D25: =+C25*9% | E25: =+D25 | F25: =IF(D25>0," ",C25*18%)
A26: 3286 | B26: COMMISION ON PMJJBY LIC | D26: =+C26*9% | E26: =+D26 | F26: =IF(D26>0," ",C26*18%)
A27: 3287 | B27: COMM. ON PMSBY NEW INDIA ASSURANCE | D27: =+C27*9% | E27: =+D27 | F27: =IF(D27>0," ",C27*18%)
A28: 3291 | B28: CIBIL CHARGES | D28: =+C28*9% | E28: =+D28 | F28: =IF(D28>0," ",C28*18%)
A29: 3296 | B29: RTGS/NEFT MANUAL CHARGES | D29: =+C29*9% | E29: =+D29 | F29: =IF(D29>0," ",C29*18%)
A30: 3297 | B30: ASBA FORM PRINT CHARGES | D30: =+C30*9% | E30: =+D30 | F30: =IF(D30>0," ",C30*18%)
A31: 3298 | B31: MANDATE HANDLING CHARGES | D31: =+C31*9% | E31: =+D31 | F31: =IF(D31>0," ",C31*18%)
A32: 3299 | B32: SI EXECUTION FAILED CHARGES | D32: =+C32*9% | E32: =+D32 | F32: =IF(D32>0," ",C32*18%)
A33: 3300 | B33: INCIDENTAL CHARGES | D33: =+C33*9% | E33: =+D33 | F33: 0
A34: 3301 | B34: INOPERATIVE CHARGES | D34: =+C34*9% | E34: =+D34 | F34: =IF(D34>0," ",C34*18%)
A35: 3302 | B35: PO CANCEL CHRAGES | D35: =+C35*9% | E35: =+D35 | F35: =IF(D35>0," ",C35*18%)
A36: 3305 | B36: A/C SHARE TRANSFER FEES | D36: =+C36*9% | E36: =+D36 | F36: =IF(D36>0," ",C36*18%)
A37: 3309 | B37: MIS. INCOME WITH GST | D37: =+C37*9% | E37: =+D37 | F37: =IF(D37>0," ",C37*18%)
A38: 3310 | B38: MIS. INCOME | D38: =+C38*9% | E38: =+D38 | F38: =IF(D38>0," ",C38*18%)
A39: 3311 | B39: I/W CHQ. RET. CHARGES | D39: =+C39*9% | E39: =+D39 | F39: =IF(D39>0," ",C39*18%)
A40: 3312 | B40: O/W CHQ. RET. CHARGES | D40: =+C40*9% | E40: =+D40 | F40: =IF(D40>0," ",C40*18%)
A41: 3313 | B41: ECS RETD. CHARGES | D41: =+C41*9% | E41: =+D41 | F41: =IF(D41>0," ",C41*18%)
A42: 3314 | B42: CHQ. BOOK ISSUE CHARGES | D42: =+C42*9% | E42: =+D42 | F42: =IF(D42>0," ",C42*18%)
...

Sheet PANJRAPOLE
A1: NUTAN NAGARIK SAHAKARI BANK LTD (GUJARAT BRANCHES & HEAD OFFICE)
A3: BRANCH NAME : PANJRAPOLE BRANCH
A4: BRANCH CODE:10
A5: =+'JODHPUR-SATELLITE'!A5
A7: CODE NO. | B7: PARTICULARS | D7: GGST | E7: CGST | F7: IGST | I7: LOCKER CLOSED
A8: PL
A9: 3303 | B9: DD CANCEL CHARGES | D9: =+C9*9% | E9: =+D9 | F9: =IF(D9>0," ",C9*18%) | I9: 0
A10: 3200 | B10: COMMISION ON BILLS | D10: =+C10*9% | E10: =+D10 | F10: =IF(D10>0," ",C10*18%) | I10: 0
A11: 3215 | B11: COMMISION ON PAYORDER | D11: =+C11*9% | E11: =+D11 | F11: =IF(D11>0," ",C11*18%) | I11: 0
A12: 3220 | B12: COMMISION ON U.B.D. | D12: =+C12*9% | E12: =+D12 | F12: =IF(D12>0," ",C12*18%) | I12: 0
A13: 3225 | B13: COMMISION I.B.C. | D13: =+C13*9% | E13: =+D13 | F13: =IF(D13>0," ",C13*18%) | I13: 0
A14: 3230 | B14: COMMISION ON GUARANTEE | D14: =+C14*9% | E14: =+D14 | F14: 0 | I14: 0
A15: 3235 | B15: COMMISION ON DEMAND DRAFT | D15: =+C15*9% | E15: =+D15 | F15: =IF(D15>0," ",C15*18%) | I15: 0
A16: 3240 | B16: COMMISION ON U.B.C. | D16: =+C16*9% | E16: =+D16 | F16: =IF(D16>0," ",C16*18%) | I16: 0
A17: 3245 | B17: COMMISION ON L.C. | D17: =+C17*9% | E17: =+D17 | F17: =IF(D17>0," ",C17*18%) | I17: 0
A18: 3250 | B18: COMMISSION ON GUARANTEE | D18: =+C18*9% | E18: =+D18 | F18: =IF(D18>0," ",C18*18%) | I18: 0
A19: 3270 | B19: PROCESSING CHARGE | D19: =+C19*9% | E19: =+D19 | F19: =IF(D19>0," ",C19*18%) | I19: 0
A20: 3271 | B20: RENEWAL FEES | D20: =+C20*9% | E20: =+D20 | F20: =IF(D20>0," ",C20*18%) | I20: 0
A21: 3274 | B21: INCOME FROM E-STAMPING | I21: 0
A22: 3276 | B22: COMMISION ON PAN | D22: =+C22*9% | E22: =+D22 | F22: 0 | I22: 0
A23: 3280 | B23: INSURANCE PREMIUM | D23: =+C23*9% | E23: =+D23 | F23: =IF(D23>0," ",C23*18%) | I23: 0
A24: 3281 | B24: ATM CHARGES | D24: =+C24*9% | E24: =+D24 | I24: 0
A25: 3285 | B25: COMMISION ON RTGS | D25: =+C25*9% | E25: =+D25 | F25: =IF(D25>0," ",C25*18%) | I25: 0
A26: 3286 | B26: COMMISION ON PMJJBY LIC | D26: =+C26*9% | E26: =+D26 | F26: =IF(D26>0," ",C26*18%) | I26: 0
A27: 3287 | B27: COMM. ON PMSBY NEW INDIA ASSURANCE | D27: =+C27*9% | E27: =+D27 | F27: =IF(D27>0," ",C27*18%) | I27: 0
A28: 3291 | B28: CIBIL CHARGES | D28: =+C28*9% | E28: =+D28 | F28: =IF(D28>0," ",C28*18%) | I28: 0
A29: 3296 | B29: RTGS/NEFT MANUAL CHARGES | D29: =+C29*9% | E29: =+D29 | F29: =IF(D29>0," ",C29*18%) | I29: 0
A30: 3297 | B30: ASBA FORM PRINT CHARGES | D30: =+C30*9% | E30: =+D30 | F30: =IF(D30>0," ",C30*18%) | I30: 0
A31: 3298 | B31: MANDATE HANDLING CHARGES | D31: =+C31*9% | E31: =+D31 | F31: =IF(D31>0," ",C31*18%) | I31: 0
A32: 3299 | B32: SI EXECUTION FAILED CHARGES | D32: =+C32*9% | E32: =+D32 | F32: =IF(D32>0," ",C32*18%) | I32: 0
A33: 3300 | B33: INCIDENTAL CHARGES | D33: =+C33*9% | E33: =+D33 | F33: 0 | I33: 0
A34: 3301 | B34: INOPERATIVE CHARGES | D34: =+C34*9% | E34: =+D34 | F34: =IF(D34>0," ",C34*18%) | I34: 0
A35: 3302 | B35: PO CANCEL CHARGES | D35: =+C35*9% | E35: =+D35 | F35: =IF(D35>0," ",C35*18%) | I35: 0
A36: 3305 | B36: A/C SHARE TRANSFER FEES | D36: =+C36*9% | E36: =+D36 | F36: =IF(D36>0," ",C36*18%) | I36: 0
A37: 3309 | B37: MIS. INCOME WITH GST | D37: =+C37*9% | E37: =+D37 | F37: =IF(D37>0," ",C37*18%) | I37: 0
A38: 3310 | B38: MIS. INCOME | D38: =+C38*9% | E38: =+D38 | F38: 0 | I38: 0
A39: 3311 | B39: I/W CHQ. RET. CHARGES | D39: =+C39*9% | E39: =+D39 | F39: =IF(D39>0," ",C39*18%) | I39: 0
A40: 3312 | B40: O/W CHQ. RET. CHARGES | D40: =+C40*9% | E40: =+D40 | F40: =IF(D40>0," ",C40*18%) | I40: 0
A41: 3313 | B41: ECS RETD. CHARGES | D41: =+C41*9% | E41: =+D41 | F41: =IF(D41>0," ",C41*18%) | I41: 0
A42: 3314 | B42: CHQ. BOOK ISSUE CHARGES | D42: =+C42*9% | E42: =+D42 | F42: =IF(D42>0," ",C42*18%) | I42: 0
...

Sheet ASHRAM ROAD
A1: NUTAN NAGARIK SAHAKARI BANK LTD (GUJARAT BRANCHES & HEAD OFFICE)
A3: BRANCH NAME : ASHRAM ROAD BRANCH
A4: BRANCH CODE: 05
A5: =+PANJRAPOLE!A5
A7: CODE NO. | B7: PARTICULARS | D7: GGST | E7: CGST | F7: IGST | I7: LOCKER CLOSED CREDIT
A8: PL
A9: 3303 | B9: DD CANCEL CHARGES | D9: =+C9*9% | E9: =+D9 | F9: =IF(D9>0," ",C9*18%) | I9: 0
A10: 3200 | B10: COMMISION ON BILLS | D10: =+C10*9% | E10: =+D10 | F10: =IF(D10>0," ",C10*18%) | I10: 0
A11: 3215 | B11: COMMISION ON PAYORDER | D11: =+C11*9% | E11: =+D11 | F11: =IF(D11>0," ",C11*18%) | I11: 0
A12: 3220 | B12: COMMISION ON U.B.D. | D12: =+C12*9% | E12: =+D12 | F12: =IF(D12>0," ",C12*18%) | I12: 0
A13: 3225 | B13: COMMISION I.B.C. | D13: =+C13*9% | E13: =+D13 | F13: =IF(D13>0," ",C13*18%) | I13: 0
A14: 3230 | B14: COMMISION ON GUARANTEE | D14: =+C14*9% | E14: =+D14 | F14: 0 | I14: 0 | K14: 0 | L14: 0 | M14: 0 | N14: 0
A15: 3235 | B15: COMMISION ON DEMAND DRAFT | D15: =+C15*9% | E15: =+D15 | F15: =IF(D15>0," ",C15*18%) | I15: 0
A16: 3240 | B16: COMMISION ON U.B.C. | D16: =+C16*9% | E16: =+D16 | F16: =IF(D16>0," ",C16*18%) | I16: 0
A17: 3245 | B17: COMMISION ON L.C. | D17: =+C17*9% | E17: =+D17 | F17: =IF(D17>0," ",C17*18%) | I17: 0
A18: 3250 | B18: COMMISSION ON GUARANTEE | D18: =+C18*9% | E18: =+D18 | F18: =IF(D18>0," ",C18*18%) | I18: 0
A19: 3270 | B19: PROCESSING CHARGE | D19: =+C19*9% | E19: =+D19 | I19: 0
A20: 3271 | B20: RENEWAL FEES | D20: =+C20*9% | E20: =+D20 | I20: 0
A21: 3274 | B21: INCOME FROM E-STAMPING | I21: 0
A22: 3276 | B22: COMMISION ON PAN | D22: =+C22*9% | E22: =+D22 | F22: =IF(D22>0," ",C22*18%) | I22: 0
A23: 3280 | B23: INSURANCE PREMIUM | D23: =+C23*9% | E23: =+D23 | F23: =IF(D23>0," ",C23*18%) | I23: 0
A24: 3281 | B24: ATM CHARGES | D24: =+C24*9% | E24: =+D24 | I24: 0
A25: 3285 | B25: COMMISION ON RTGS | D25: =+C25*9% | E25: =+D25 | F25: =IF(D25>0," ",C25*18%) | I25: 0
A26: 3286 | B26: COMMISION ON PMJJBY LIC | D26: =+C26*9% | E26: =+D26 | F26: =IF(D26>0," ",C26*18%) | I26: 0
A27: 3287 | B27: COMM. ON PMSBY NEW INDIA ASSURANCE | D27: =+C27*9% | E27: =+D27 | F27: =IF(D27>0," ",C27*18%) | I27: 0
A28: 3291 | B28: CIBIL CHARGES | D28: =+C28*9% | E28: =+D28 | F28: =IF(D28>0," ",C28*18%) | I28: 0
A29: 3296 | B29: RTGS/NEFT MANUAL CHARGES | D29: =+C29*9% | E29: =+D29 | F29: =IF(D29>0," ",C29*18%) | I29: 0
A30: 3297 | B30: ASBA FORM PRINT CHARGES | D30: =+C30*9% | E30: =+D30 | F30: =IF(D30>0," ",C30*18%) | I30: 0
A31: 3298 | B31: MANDATE HANDLING CHARGES | D31: =+C31*9% | E31: =+D31 | F31: =IF(D31>0," ",C31*18%) | I31: 0
A32: 3299 | B32: SI EXECUTION FAILED CHARGES | D32: =+C32*9% | E32: =+D32 | F32: =IF(D32>0," ",C32*18%) | I32: 0
A33: 3300 | B33: INCIDENTAL CHARGES | D33: =+C33*9% | E33: =+D33 | F33: =IF(D33>0," ",C33*18%) | I33: 0
A34: 3301 | B34: INOPERATIVE CHARGES | D34: =+C34*9% | E34: =+D34 | F34: =IF(D34>0," ",C34*18%) | I34: 0
A35: 3302 | B35: PO CANCEL CHARGES | D35: =+C35*9% | E35: =+D35 | F35: =IF(D35>0," ",C35*18%) | I35: 0
A36: 3305 | B36: A/C SHARE TRANSFER FEES | D36: =+C36*9% | E36: =+D36 | F36: =IF(D36>0," ",C36*18%) | I36: 0
A37: 3309 | B37: MIS. INCOME WITH GST | D37: =+C37*9% | E37: =+D37 | F37: =IF(D37>0," ",C37*18%) | I37: 0
A38: 3310 | B38: MIS. INCOME | D38: =+C38*9% | E38: =+D38 | F38: 0 | I38: 0
A39: 3311 | B39: I/W CHQ. RET. CHARGES | D39: =+C39*9% | E39: =+D39 | F39: 0 | I39: 0 | M39: =3884-4463
A40: 3312 | B40: O/W CHQ. RET. CHARGES | D40: =+C40*9% | E40: =+D40 | F40: =IF(D40>0," ",C40*18%) | I40: 0
A41: 3313 | B41: ECS RETD. CHARGES | D41: =+C41*9% | E41: =+D41 | F41: =IF(D41>0," ",C41*18%) | I41: 0
A42: 3314 | B42: CHQ. BOOK ISSUE CHARGES | D42: =+C42*9% | E42: =+D42 | F42: =IF(D42>0," ",C42*18%) | I42: 0
...

Sheet NARAYANNAGAR
A1: NUTAN NAGARIK SAHAKARI BANK LTD (GUJARAT BRANCHES & HEAD OFFICE)
A3: BRANCH NAME :NARAYANNAGAR ROAD BRANCH
A4: BRANCH CODE: 15
A5: =+'ODHAV '!$A$5
A7: CODE NO. | B7: PARTICULARS | D7: GGST | E7: CGST | F7: IGST | I7: LOCKER CLOSED CREDIT
A8: PL
A9: 3303 | B9: DD CANCEL CHARGES | D9: =+C9*9% | E9: =+D9 | F9: =IF(D9>0," ",C9*18%) | I9: 0
A10: 3200 | B10: COMMISION ON BILLS | D10: =+C10*9% | E10: =+D10 | F10: =IF(D10>0," ",C10*18%) | I10: 0
A11: 3215 | B11: COMMISION ON PAYORDER | D11: =+C11*9% | E11: =+D11 | F11: =IF(D11>0," ",C11*18%) | I11: 0
A12: 3220 | B12: COMMISION ON U.B.D. | D12: =+C12*9% | E12: =+D12 | F12: =IF(D12>0," ",C12*18%) | I12: 0
A13: 3225 | B13: COMMISION I.B.C. | D13: =+C13*9% | E13: =+D13 | F13: =IF(D13>0," ",C13*18%) | I13: 0
A14: 3230 | B14: COMMISION ON GUARANTEE | D14: =+C14*9% | E14: =+D14 | F14: =IF(D14>0," ",C14*18%) | I14: 0
A15: 3235 | B15: COMMISION ON DEMAND DRAFT | D15: =+C15*9% | E15: =+D15 | F15: =IF(D15>0," ",C15*18%) | I15: 0
A16: 3240 | B16: COMMISION ON U.B.C. | D16: =+C16*9% | E16: =+D16 | F16: =IF(D16>0," ",C16*18%) | I16: 0
A17: 3245 | B17: COMMISION ON L.C. | D17: =+C17*9% | E17: =+D17 | F17: =IF(D17>0," ",C17*18%) | I17: 0
A18: 3250 | B18: COMMISSION ON GUARANTEE | D18: =+C18*9% | E18: =+D18 | F18: =IF(D18>0," ",C18*18%) | I18: 0
A19: 3270 | B19: PROCESSING CHARGE | D19: =+C19*9% | E19: =+D19 | F19: =IF(D19>0," ",C19*18%) | I19: 0
A20: 3271 | B20: RENEWAL FEES | D20: =+C20*9% | E20: =+D20 | F20: =IF(D20>0," ",C20*18%) | I20: 0
A21: 3274 | B21: INCOME FROM E-STAMPING | F21: =IF(D21>0," ",C21*18%) | I21: 0
A22: 3276 | B22: COMMISION ON PAN | D22: =+C22*9% | E22: =+D22 | F22: =IF(D22>0," ",C22*18%) | I22: 0
A23: 3280 | B23: INSURANCE PREMIUM | D23: =+C23*9% | E23: =+D23 | F23: =IF(D23>0," ",C23*18%) | I23: 0
A24: 3281 | B24: ATM CHARGES | D24: =+C24*9% | E24: =+D24 | F24: =IF(D24>0," ",C24*18%) | I24: 0
A25: 3285 | B25: COMMISION ON RTGS | D25: =+C25*9% | E25: =+D25 | F25: =IF(D25>0," ",C25*18%) | I25: 0
A26: 3286 | B26: COMMISION ON PMJJBY LIC | D26: =+C26*9% | E26: =+D26 | F26: =IF(D26>0," ",C26*18%) | I26: 0
A27: 3287 | B27: COMM. ON PMSBY NEW INDIA ASSURANCE | D27: =+C27*9% | E27: =+D27 | F27: =IF(D27>0," ",C27*18%) | I27: 0
A28: 3291 | B28: CIBIL CHARGES | D28: =+C28*9% | E28: =+D28 | F28: =IF(D28>0," ",C28*18%) | I28: 0
A29: 3296 | B29: RTGS/NEFT MANUAL CHARGES | D29: =+C29*0.09 | E29: =+D29 | F29: =IF(D29>0," ",C29*18%) | I29: 0
A30: 3297 | B30: ASBA FORM PRINT CHARGES | D30: =+C30*9% | E30: =+D30 | F30: =IF(D30>0," ",C30*18%) | I30: 0
A31: 3298 | B31: MANDATE HANDLING CHARGES | D31: =+C31*9% | E31: =+D31 | F31: =IF(D31>0," ",C31*18%) | I31: 0
A32: 3299 | B32: SI EXECUTION FAILED CHARGES | D32: =+C32*9% | E32: =+D32 | F32: =IF(D32>0," ",C32*18%) | I32: 0 | J32: =+C33-J33
A33: 3300 | B33: INCIDENTAL CHARGES | D33: =+C33*9% | E33: =+D33 | F33: =IF(D33>0," ",C33*18%) | I33: 0 | J33: 163981
A34: 3301 | B34: INOPERATIVE CHARGES | D34: =+C34*9% | E34: =+D34 | F34: =IF(D34>0," ",C34*18%) | I34: 0
A35: 3302 | B35: PO CANCEL CHARGES | D35: =+C35*9% | E35: =+D35 | F35: =IF(D35>0," ",C35*18%) | I35: 0
A36: 3305 | B36: A/C SHARE TRANSFER FEES | D36: =+C36*9% | E36: =+D36 | F36: =IF(D36>0," ",C36*18%) | I36: 0
A37: 3309 | B37: MIS. INCOME WITH GST | D37: =+C37*9% | E37: =+D37 | F37: =IF(D37>0," ",C37*18%) | I37: 0
A38: 3310 | B38: MIS. INCOME | D38: =+C38*9% | E38: =+D38 | F38: =IF(D38>0," ",C38*18%) | I38: 0
A39: 3311 | B39: I/W CHQ. RET. CHARGES | D39: =+C39*9% | E39: =+D39 | F39: =IF(D39>0," ",C39*18%) | I39: 0
A40: 3312 | B40: O/W CHQ. RET. CHARGES | D40: =+C40*9% | E40: =+D40 | F40: =IF(D40>0," ",C40*18%) | I40: 0
A41: 3313 | B41: ECS RETD. CHARGES | D41: =+C41*9% | E41: =+D41 | F41: =IF(D41>0," ",C41*18%) | I41: 0
A42: 3314 | B42: CHQ. BOOK ISSUE CHARGES | D42: =+C42*9% | E42: =+D42 | F42: =IF(D42>0," ",C42*18%) | I42: 0 | J42: =6150-C42
...

Sheet NARANPURA
A1: NUTAN NAGARIK SAHAKARI BANK LTD (GUJARAT BRANCHES & HEAD OFFICE)
A3: BRANCH NAME :NARANPURA BRANCH
A4: BRANCH CODE: 14
A5: =+'ODHAV '!$A$5
A7: CODE NO. | B7: PARTICULARS | D7: GGST | E7: CGST | F7: IGST | I7: LOCKER CLOSED CREDIT
A8: PL
A9: 3110 | B9: OVER DRAFT | D9: =+C9*9% | E9: =+D9 | F9: =IF(D9>0," ",C9*18%) | I9: 0
A10: 3200 | B10: COMMISION ON BILLS | D10: =+C10*9% | E10: =+D10 | F10: =IF(D10>0," ",C10*18%) | I10: 0
A11: 3215 | B11: COMMISION ON PAYORDER | D11: =+C11*9% | E11: =+D11 | F11: =IF(D11>0," ",C11*18%) | I11: 0
A12: 3220 | B12: COMMISION ON U.B.D. | D12: =+C12*9% | E12: =+D12 | F12: =IF(D12>0," ",C12*18%) | I12: 0
A13: 3225 | B13: COMMISION I.B.C. | D13: =+C13*9% | E13: =+D13 | F13: =IF(D13>0," ",C13*18%) | I13: 0
A14: 3230 | B14: COMMISION ON GUARANTEE | D14: =+C14*9% | E14: =+D14 | F14: =IF(D14>0," ",C14*18%) | I14: 0
A15: 3235 | B15: COMMISION ON DEMAND DRAFT | D15: =+C15*9% | E15: =+D15 | F15: =IF(D15>0," ",C15*18%) | I15: 0
A16: 3240 | B16: COMMISION ON U.B.C. | D16: =+C16*9% | E16: =+D16 | F16: =IF(D16>0," ",C16*18%) | I16: 0
A17: 3245 | B17: COMMISION ON L.C. | D17: =+C17*9% | E17: =+D17 | F17: =IF(D17>0," ",C17*18%) | I17: 0
A18: 3250 | B18: COMMISSION ON GUARANTEE | D18: =+C18*9% | E18: =+D18 | F18: =IF(D18>0," ",C18*18%) | I18: 0
A19: 3270 | B19: PROCESSING CHARGE | D19: =+C19*9% | E19: =+D19 | F19: =IF(D19>0," ",C19*18%) | I19: 0
A20: 3271 | B20: RENEWAL FEES | D20: =+C20*9% | E20: =+D20 | F20: =IF(D20>0," ",C20*18%) | I20: 0
A21: 3274 | B21: INCOME FROM E-STAMPING | D21: =+C21*9% | E21: =+D21 | F21: =IF(D21>0," ",C21*18%) | I21: 0
A22: 3276 | B22: COMMISION ON PAN | D22: =+C22*9% | E22: =+D22 | F22: =IF(D22>0," ",C22*18%) | I22: 0
A23: 3280 | B23: INSURANCE PREMIUM | D23: =+C23*9% | E23: =+D23 | F23: =IF(D23>0," ",C23*18%) | I23: 0
A24: 3281 | B24: ATM CHARGES | D24: =+C24*9% | E24: =+D24 | F24: =IF(D24>0," ",C24*18%) | I24: 0
A25: 3285 | B25: COMMISION ON RTGS | D25: =+C25*9% | E25: =+D25 | F25: =IF(D25>0," ",C25*18%) | I25: 0
A26: 3286 | B26: COMMISION ON PMJJBY LIC | D26: =+C26*9% | E26: =+D26 | F26: =IF(D26>0," ",C26*18%) | I26: 0
A27: 3287 | B27: COMM. ON PMSBY NEW INDIA ASSURANCE | D27: =+C27*9% | E27: =+D27 | F27: =IF(D27>0," ",C27*18%) | I27: 0
A28: 3291 | B28: CIBIL CHARGES | D28: =+C28*9% | E28: =+D28 | F28: =IF(D28>0," ",C28*18%) | I28: 0
A29: 3296 | B29: RTGS/NEFT MANUAL CHARGES | D29: =+C29*9% | E29: =+D29 | F29: =IF(D29>0," ",C29*18%) | I29: 0
A30: 3297 | B30: ASBA FORM PRINT CHARGES | D30: =+C30*9% | E30: =+D30 | F30: =IF(D30>0," ",C30*18%) | I30: 0
A31: 3298 | B31: MANDATE HANDLING CHARGES | D31: =+C31*9% | E31: =+D31 | F31: =IF(D31>0," ",C31*18%) | I31: 0
A32: 3299 | B32: SI EXECUTION FAILED CHARGES | D32: =+C32*9% | E32: =+D32 | F32: =IF(D32>0," ",C32*18%) | I32: 0
A33: 3300 | B33: INCIDENTAL CHARGES | D33: =+C33*9% | E33: =+D33 | F33: =IF(D33>0," ",C33*18%) | I33: 0
A34: 3301 | B34: INOPERATIVE CHARGES | D34: =+C34*9% | E34: =+D34 | F34: =IF(D34>0," ",C34*18%) | I34: 0
A35: 3302 | B35: PO CANCEL CHARGES | D35: =+C35*9% | E35: =+D35 | F35: =IF(D35>0," ",C35*18%) | I35: 0
A36: 3305 | B36: A/C SHARE TRANSFER FEES | D36: =+C36*9% | E36: =+D36 | F36: =IF(D36>0," ",C36*18%) | I36: 0
A37: 3309 | B37: MIS. INCOME WITH GST | D37: =+C37*9% | E37: =+D37 | F37: =IF(D37>0," ",C37*18%) | I37: 0
A38: 3310 | B38: MIS. INCOME | D38: =+C38*9% | E38: =+D38 | F38: 0 | I38: 0
A39: 3311 | B39: I/W CHQ. RET. CHARGES | D39: =+C39*9% | E39: =+D39 | F39: 0 | I39: 0
A40: 3312 | B40: O/W CHQ. RET. CHARGES | D40: =+C40*9% | E40: =+D40 | F40: =IF(D40>0," ",C40*18%) | I40: 0
A41: 3313 | B41: ECS RETD. CHARGES | D41: =+C41*9% | E41: =+D41 | F41: =IF(D41>0," ",C41*18%) | I41: 0
A42: 3314 | B42: CHQ. BOOK ISSUE CHARGES | D42: =+C42*9% | E42: =+D42 | F42: =IF(D42>0," ",C42*18%) | I42: 0
...

Sheet DRIVE IN
A1: NUTAN NAGARIK SAHAKARI BANK LTD (GUJARAT BRANCHES & HEAD OFFICE)
A3: BRANCH NAME :DRIVE IN BRANCH
A4: BRANCH CODE: 09
A5: =+'ODHAV '!$A$5
A7: CODE NO. | B7: PARTICULARS | D7: GGST | E7: CGST | F7: IGST | I7: LOCKER CLOSED
A8: PL
A9: 3380 | B9: STATMENT CHARGES | D9: =+C9*9% | E9: =+D9 | F9: =IF(D9>0," ",C9*18%) | I9: 0
A10: 3200 | B10: COMMISION ON BILLS | D10: =+C10*9% | E10: =+D10 | F10: =IF(D10>0," ",C10*18%) | I10: 0
A11: 3215 | B11: COMMISION ON PAYORDER | D11: =+C11*9% | E11: =+D11 | F11: =IF(D11>0," ",C11*18%) | I11: 0
A12: 3220 | B12: COMMISION ON U.B.D. | D12: =+C12*9% | E12: =+D12 | F12: =IF(D12>0," ",C12*18%) | I12: 0
A13: 3225 | B13: COMMISION I.B.C. | D13: =+C13*9% | E13: =+D13 | F13: =IF(D13>0," ",C13*18%) | I13: 0
A14: 3230 | B14: COMMISION ON GUARANTEE | D14: =+C14*9% | E14: =+D14 | F14: =IF(D14>0," ",C14*18%) | I14: 0
A15: 3235 | B15: COMMISION ON DEMAND DRAFT | D15: =+C15*9% | E15: =+D15 | F15: =IF(D15>0," ",C15*18%) | I15: 0
A16: 3240 | B16: COMMISION ON U.B.C. | D16: =+C16*9% | E16: =+D16 | F16: =IF(D16>0," ",C16*18%) | I16: 0
A17: 3245 | B17: COMMISION ON L.C. | D17: =+C17*9% | E17: =+D17 | F17: =IF(D17>0," ",C17*18%) | I17: 0
A18: 3250 | B18: COMMISSION ON GUARANTEE | D18: =+C18*9% | E18: =+D18 | F18: =IF(D18>0," ",C18*18%) | I18: 0
A19: 3270 | B19: PROCESSING CHARGE | D19: =+C19*9% | E19: =+D19 | F19: =IF(D19>0," ",C19*18%) | I19: 0
A20: 3271 | B20: RENEWAL FEES | D20: =+C20*9% | E20: =+D20 | F20: =IF(D20>0," ",C20*18%) | I20: 0
A21: 3274 | B21: INCOME FROM E-STAMPING | D21: =+C21*9% | E21: =+D21 | F21: =IF(D21>0," ",C21*18%) | I21: 0
A22: 3276 | B22: COMMISION ON PAN | D22: =+C22*9% | E22: =+D22 | F22: =IF(D22>0," ",C22*18%) | I22: 0
A23: 3280 | B23: INSURANCE PREMIUM | D23: =+C23*9% | E23: =+D23 | F23: =IF(D23>0," ",C23*18%) | I23: 0
A24: 3281 | B24: ATM CHARGES | D24: =+C24*9% | E24: =+D24 | F24: =IF(D24>0," ",C24*18%) | I24: 0
A25: 3285 | B25: COMMISION ON RTGS | D25: =+C25*9% | E25: =+D25 | F25: =IF(D25>0," ",C25*18%) | I25: 0
A26: 3286 | B26: COMMISION ON PMJJBY LIC | D26: =+C26*9% | E26: =+D26 | F26: =IF(D26>0," ",C26*18%) | I26: 0
A27: 3287 | B27: COMM. ON PMSBY NEW INDIA ASSURANCE | D27: =+C27*9% | E27: =+D27 | F27: =IF(D27>0," ",C27*18%) | I27: 0
A28: 3291 | B28: CIBIL CHARGES | D28: =+C28*9% | E28: =+D28 | F28: =IF(D28>0," ",C28*18%) | I28: 0
A29: 3296 | B29: RTGS/NEFT MANUAL CHARGES | D29: =+C29*9% | E29: =+D29 | F29: =IF(D29>0," ",C29*18%) | I29: 0
A30: 3297 | B30: ASBA FORM PRINT CHARGES | D30: =+C30*9% | E30: =+D30 | F30: =IF(D30>0," ",C30*18%) | I30: 0
A31: 3298 | B31: MANDATE HANDLING CHARGES | D31: =+C31*9% | E31: =+D31 | F31: =IF(D31>0," ",C31*18%) | I31: 0
A32: 3299 | B32: SI EXECUTION FAILED CHARGES | D32: =+C32*9% | E32: =+D32 | F32: =IF(D32>0," ",C32*18%) | I32: 0
A33: 3300 | B33: INCIDENTAL CHARGES | D33: =+C33*9% | E33: =+D33 | F33: 0 | I33: 0
A34: 3301 | B34: INOPERATIVE CHARGES | D34: =+C34*9% | E34: =+D34 | F34: =IF(D34>0," ",C34*18%) | I34: 0
A35: 3302 | B35: PO CANCEL CHARGES | D35: =+C35*9% | E35: =+D35 | F35: =IF(D35>0," ",C35*18%) | I35: 0
A36: 3305 | B36: A/C SHARE TRANSFER FEES | D36: =+C36*9% | E36: =+D36 | F36: =IF(D36>0," ",C36*18%) | I36: 0
A37: 3309 | B37: MIS. INCOME WITH GST | D37: =+C37*9% | E37: =+D37 | F37: =IF(D37>0," ",C37*18%) | I37: 0
A38: 3310 | B38: MIS. INCOME | D38: =+C38*9% | E38: =+D38 | F38: =IF(D38>0," ",C38*18%) | I38: 0
A39: 3311 | B39: I/W CHQ. RET. CHARGES | D39: =+C39*9% | E39: =+D39 | F39: =IF(D39>0," ",C39*18%) | I39: 0
A40: 3312 | B40: O/W CHQ. RET. CHARGES | D40: =+C40*9% | E40: =+D40 | F40: =IF(D40>0," ",C40*18%) | I40: 0
A41: 3313 | B41: ECS RETD. CHARGES | D41: =+C41*9% | E41: =+D41 | F41: =IF(D41>0," ",C41*18%) | I41: 0
A42: 3314 | B42: CHQ. BOOK ISSUE CHARGES | D42: =+C42*9% | E42: =+D42 | F42: =IF(D42>0," ",C42*18%) | I42: 0
...

Sheet VASANA 
A1: NUTAN NAGARIK SAHAKARI BANK LTD (GUJARAT BRANCHES & HEAD OFFICE)
A3: BRANCH NAME : VASNA BRANCH
A4: BRANCH CODE: 8
A5: =+'ODHAV '!$A$5
A7: CODE NO. | B7: PARTICULARS | D7: GGST | E7: CGST | F7: IGST | I7: LOCKER CLOSED CREDIT
A8: PL
A9: 3303 | B9: DD CANCEL CHARGES | D9: =+C9*9% | E9: =+D9 | F9: =IF(D9>0," ",C9*18%) | I9: 0
A10: 3200 | B10: COMMISION ON BILLS | D10: =+C10*9% | E10: =+D10 | F10: =IF(D10>0," ",C10*18%) | I10: 0
A11: 3215 | B11: COMMISION ON PAYORDER | D11: =+C11*9% | E11: =+D11 | F11: =IF(D11>0," ",C11*18%) | I11: 0
A12: 3220 | B12: COMMISION ON U.B.D. | D12: =+C12*9% | E12: =+D12 | F12: =IF(D12>0," ",C12*18%) | I12: 0
A13: 3225 | B13: COMMISION I.B.C. | D13: =+C13*9% | E13: =+D13 | F13: =IF(D13>0," ",C13*18%) | I13: 0
A14: 3230 | B14: COMMISION ON GUARANTEE | D14: =+C14*9% | E14: =+D14 | F14: =IF(D14>0," ",C14*18%) | I14: 0
A15: 3235 | B15: COMMISION ON DEMAND DRAFT | D15: =+C15*9% | E15: =+D15 | F15: =IF(D15>0," ",C15*18%) | I15: 0
A16: 3240 | B16: COMMISION ON U.B.C. | D16: =+C16*9% | F16: =IF(D16>0," ",C16*18%) | I16: 0
A17: 3245 | B17: COMMISION ON L.C. | D17: =+C17*9% | E17: =+D17 | F17: =IF(D17>0," ",C17*18%) | I17: 0
A18: 3250 | B18: COMMISSION ON GUARANTEE | D18: =+C18*9% | E18: =+D18 | F18: =IF(D18>0," ",C18*18%) | I18: 0
A19: 3270 | B19: PROCESSING CHARGE | D19: =+C19*9% | E19: =+D19 | F19: =IF(D19>0," ",C19*18%) | I19: 0
A20: 3271 | B20: RENEWAL FEES | D20: =+C20*9% | E20: =+D20 | F20: =IF(D20>0," ",C20*18%) | I20: 0
A21: 3274 | B21: INCOME FROM E-STAMPING | D21: =+C21*9% | E21: =+D21 | I21: 0
A22: 3276 | B22: COMMISION ON PAN | D22: =+C22*9% | E22: =+D22 | F22: =IF(D22>0," ",C22*18%) | I22: 0
A23: 3280 | B23: INSURANCE PREMIUM | D23: =+C23*9% | E23: =+D23 | F23: =IF(D23>0," ",C23*18%) | I23: 0
A24: 3281 | B24: ATM CHARGES | D24: =+C24*9% | E24: =+D24 | F24: 0 | I24: 0
A25: 3285 | B25: COMMISION ON RTGS | D25: =+C25*9% | E25: =+D25 | F25: =IF(D25>0," ",C25*18%) | I25: 0
A26: 3286 | B26: COMMISION ON PMJJBY LIC | D26: =+C26*9% | E26: =+D26 | F26: =IF(D26>0," ",C26*18%) | I26: 0
A27: 3287 | B27: COMM. ON PMSBY NEW INDIA ASSURANCE | D27: =+C27*9% | E27: =+D27 | F27: =IF(D27>0," ",C27*18%) | I27: 0
A28: 3291 | B28: CIBIL CHARGES | D28: =+C28*9% | E28: =+D28 | F28: =IF(D28>0," ",C28*18%) | I28: 0
A29: 3296 | B29: RTGS/NEFT MANUAL CHARGES | D29: =+C29*9% | E29: =+D29 | F29: =IF(D29>0," ",C29*18%) | I29: 0
A30: 3297 | B30: ASBA FORM PRINT CHARGES | D30: =+C30*9% | E30: =+D30 | F30: =IF(D30>0," ",C30*18%) | I30: 0
A31: 3298 | B31: MANDATE HANDLING CHARGES | D31: =+C31*9% | E31: =+D31 | F31: =IF(D31>0," ",C31*18%) | I31: 0
A32: 3299 | B32: SI EXECUTION FAILED CHARGES | D32: =+C32*9% | E32: =+D32 | F32: =IF(D32>0," ",C32*18%) | I32: 0
A33: 3300 | B33: INCIDENTAL CHARGES | D33: =+C33*9% | E33: =+D33 | I33: 0
A34: 3301 | B34: INOPERATIVE CHARGES | D34: =+C34*9% | E34: =+D34 | F34: =IF(D34>0," ",C34*18%) | I34: 0
A35: 3302 | B35: PO CANCEL CHARGES | D35: =+C35*9% | E35: =+D35 | F35: =IF(D35>0," ",C35*18%) | I35: 0
A36: 3305 | B36: A/C SHARE TRANSFER FEES | D36: =+C36*9% | E36: =+D36 | F36: =IF(D36>0," ",C36*18%) | I36: 0
A37: 3309 | B37: MIS. INCOME WITH GST | D37: =+C37*2.5% | E37: =+D37 | F37: =IF(D37>0," ",C37*18%) | I37: 0
A38: 3310 | B38: MIS. INCOME | D38: =+C38*9% | E38: =+D38 | F38: =IF(D38>0," ",C38*18%) | I38: 0
A39: 3311 | B39: I/W CHQ. RET. CHARGES | D39: =+C39*9% | E39: =+D39 | F39: =IF(D39>0," ",C39*18%) | I39: 0
A40: 3312 | B40: O/W CHQ. RET. CHARGES | D40: =+C40*9% | E40: =+D40 | F40: =IF(D40>0," ",C40*18%) | I40: 0
A41: 3313 | B41: ECS RETD. CHARGES | D41: =+C41*9% | E41: =+D41 | F41: =IF(D41>0," ",C41*18%) | I41: 0
A42: 3314 | B42: CHQ. BOOK ISSUE CHARGES | D42: =+C42*9% | E42: =+D42 | F42: =IF(D42>0," ",C42*18%) | I42: 0
...

Sheet SURAT
A1: NUTAN NAGARIK SAHAKARI BANK LTD (GUJARAT BRANCHES & HEAD OFFICE)
A3: BRANCH NAME : SURAT BRANCH
A4: BRANCH CODE: 41
A5: =+'ODHAV '!$A$5
A7: CODE NO. | B7: PARTICULARS | D7: GGST | E7: CGST | F7: IGST | I7: LOCKER CLOSED CREDIT
A8: PL
A9: 3303 | B9: DD CANCEL CHARGES | D9: =+C9*9% | E9: =+D9 | F9: =IF(D9>0," ",C9*18%) | I9: 0
A10: 3200 | B10: COMMISION ON BILLS | D10: =+C10*9% | E10: =+D10 | F10: =IF(D10>0," ",C10*18%) | I10: 0
A11: 3215 | B11: COMMISION ON PAYORDER | D11: =+C11*9% | E11: =+D11 | F11: =IF(D11>0," ",C11*18%) | I11: 0
A12: 3220 | B12: COMMISION ON U.B.D. | D12: =+C12*9% | E12: =+D12 | F12: =IF(D12>0," ",C12*18%) | I12: 0
A13: 3225 | B13: COMMISION I.B.C. | D13: =+C13*9% | E13: =+D13 | F13: =IF(D13>0," ",C13*18%) | I13: 0
A14: 3230 | B14: COMMISION ON GUARANTEE | D14: =+C14*9% | E14: =+D14 | F14: =IF(D14>0," ",C14*18%) | I14: 0
A15: 3235 | B15: COMMISION ON DEMAND DRAFT | D15: =+C15*9% | E15: =+D15 | F15: =IF(D15>0," ",C15*18%) | I15: 0
A16: 3240 | B16: COMMISION ON U.B.C. | D16: =+C16*9% | E16: =+D16 | F16: =IF(D16>0," ",C16*18%) | I16: 0
A17: 3245 | B17: COMMISION ON L.C. | D17: =+C17*9% | E17: =+D17 | F17: =IF(D17>0," ",C17*18%) | I17: 0
A18: 3250 | B18: COMMISSION ON GUARANTEE | D18: =+C18*9% | E18: =+D18 | F18: =IF(D18>0," ",C18*18%) | I18: 0
A19: 3270 | B19: PROCESSING CHARGE | D19: =+C19*9% | E19: =+D19 | F19: =IF(D19>0," ",C19*18%) | I19: 0
A20: 3271 | B20: RENEWAL FEES | D20: =+C20*9% | E20: =+D20 | F20: =IF(D20>0," ",C20*18%) | I20: 0
A21: 3274 | B21: INCOME FROM E-STAMPING | I21: 0
A22: 3276 | B22: COMMISION ON PAN | D22: =+C22*9% | E22: =+D22 | F22: =IF(D22>0," ",C22*18%) | I22: 0
A23: 3280 | B23: INSURANCE PREMIUM | D23: =+C23*9% | E23: =+D23 | F23: =IF(D23>0," ",C23*18%) | I23: 0
A24: 3281 | B24: ATM CHARGES | D24: =+C24*9% | E24: =+D24 | F24: =IF(D24>0," ",C24*18%) | I24: 0
A25: 3285 | B25: COMMISION ON RTGS | D25: =+C25*9% | E25: =+D25 | F25: =IF(D25>0," ",C25*18%) | I25: 0
A26: 3286 | B26: COMMISION ON PMJJBY LIC | D26: =+C26*9% | E26: =+D26 | F26: =IF(D26>0," ",C26*18%) | I26: 0
A27: 3287 | B27: COMM. ON PMSBY NEW INDIA ASSURANCE | D27: =+C27*9% | E27: =+D27 | F27: =IF(D27>0," ",C27*18%) | I27: 0
A28: 3291 | B28: CIBIL CHARGES | D28: =+C28*9% | E28: =+D28 | F28: =IF(D28>0," ",C28*18%) | I28: 0
A29: 3296 | B29: RTGS/NEFT MANUAL CHARGES | D29: =+C29*9% | E29: =+D29 | F29: =IF(D29>0," ",C29*18%) | I29: 0
A30: 3297 | B30: ASBA FORM PRINT CHARGES | D30: =+C30*9% | E30: =+D30 | F30: =IF(D30>0," ",C30*18%) | I30: 0
A31: 3298 | B31: MANDATE HANDLING CHARGES | D31: =+C31*9% | E31: =+D31 | F31: =IF(D31>0," ",C31*18%) | I31: 0
